Workbook

Sheet Sheet1
A1: frame_no | B1: timestamp_sec | C1: raw_digits | D1: weight | E1: local_median_g | F1: trend_ref_g | G1: reset_drop_g | H1: excluded | I1: weight_kept_g | J1: is_started | K1: time_corrected_s | N1: Parametreler
A2: 0 | B2: 0 | C2: 600 | D2: 6 | E2: =MEDIAN(D2:D22) | F2: =E2 | G2: =F2-E2 | H2: =IF(OR(NOT(ISNUMBER(D2)),ABS(D2-E2)>$O$3,AND($O$11=1,B2<$O$12)),1,0) | I2: =IF(H2=1,NA(),D2) | J2: =IF(AND(ISNUMBER(D2),D2>=$O$4,OR($O$11=0,B2>=$O$12)),1,0) | K2: =B2-$O$14 | N2: Medyan penceresi (satir, her yonde) | O2: 20
A3: 3 | B3: 0.1 | C3: 00 | D3: 0 | E3: =MEDIAN(D2:D23) | F3: =E3 | G3: =F3-E3 | H3: =IF(OR(NOT(ISNUMBER(D3)),ABS(D3-E3)>$O$3,AND($O$11=1,B3<$O$12)),1,0) | I3: =IF(H3=1,NA(),D3) | J3: =IF(AND(ISNUMBER(D3),D3>=$O$4,OR($O$11=0,B3>=$O$12)),1,0) | K3: =B3-$O$14 | N3: Disleme toleransi (g) | O3: 0.15
A4: 6 | B4: 0.2 | C4: 00 | D4: 0 | E4: =MEDIAN(D2:D24) | F4: =E4 | G4: =F4-E4 | H4: =IF(OR(NOT(ISNUMBER(D4)),ABS(D4-E4)>$O$3,AND($O$11=1,B4<$O$12)),1,0) | I4: =IF(H4=1,NA(),D4) | J4: =IF(AND(ISNUMBER(D4),D4>=$O$4,OR($O$11=0,B4>=$O$12)),1,0) | K4: =B4-$O$14 | N4: Baslangic esigi (g) | O4: 0.05
A5: 9 | B5: 0.3 | C5: 000 | D5: 0 | E5: =MEDIAN(D2:D25) | F5: =E5 | G5: =F5-E5 | H5: =IF(OR(NOT(ISNUMBER(D5)),ABS(D5-E5)>$O$3,AND($O$11=1,B5<$O$12)),1,0) | I5: =IF(H5=1,NA(),D5) | J5: =IF(AND(ISNUMBER(D5),D5>=$O$4,OR($O$11=0,B5>=$O$12)),1,0) | K5: =B5-$O$14 | N5: Siringa hacmi (mL) | O5: 60
A6: 12 | B6: 0.4 | C6: 000 | D6: 0 | E6: =MEDIAN(D2:D26) | F6: =E6 | G6: =F6-E6 | H6: =IF(OR(NOT(ISNUMBER(D6)),ABS(D6-E6)>$O$3,AND($O$11=1,B6<$O$12)),1,0) | I6: =IF(H6=1,NA(),D6) | J6: =IF(AND(ISNUMBER(D6),D6>=$O$4,OR($O$11=0,B6>=$O$12)),1,0) | K6: =B6-$O$14 | N6: Yogunluk (g/mL) | O6: 1
A7: 15 | B7: 0.5 | C7: 000 | D7: 0 | E7: =MEDIAN(D2:D27) | F7: =E7 | G7: =F7-E7 | H7: =IF(OR(NOT(ISNUMBER(D7)),ABS(D7-E7)>$O$3,AND($O$11=1,B7<$O$12)),1,0) | I7: =IF(H7=1,NA(),D7) | J7: =IF(AND(ISNUMBER(D7),D7>=$O$4,OR($O$11=0,B7>=$O$12)),1,0) | K7: =B7-$O$14 | N7: Reset bakis penceresi (satir) | O7: 20
A8: 18 | B8: 0.6 | C8: 00 | D8: 0 | E8: =MEDIAN(D2:D28) | F8: =E8 | G8: =F8-E8 | H8: =IF(OR(NOT(ISNUMBER(D8)),ABS(D8-E8)>$O$3,AND($O$11=1,B8<$O$12)),1,0) | I8: =IF(H8=1,NA(),D8) | J8: =IF(AND(ISNUMBER(D8),D8>=$O$4,OR($O$11=0,B8>=$O$12)),1,0) | K8: =B8-$O$14 | N8: Reset esigi (g) | O8: 5
A9: 21 | B9: 0.7 | C9: 00 | D9: 0 | E9: =MEDIAN(D2:D29) | F9: =E9 | G9: =F9-E9 | H9: =IF(OR(NOT(ISNUMBER(D9)),ABS(D9-E9)>$O$3,AND($O$11=1,B9<$O$12)),1,0) | I9: =IF(H9=1,NA(),D9) | J9: =IF(AND(ISNUMBER(D9),D9>=$O$4,OR($O$11=0,B9>=$O$12)),1,0) | K9: =B9-$O$14
A10: 24 | B10: 0.8 | C10: 00 | D10: 0 | E10: =MEDIAN(D2:D30) | F10: =E10 | G10: =F10-E10 | H10: =IF(OR(NOT(ISNUMBER(D10)),ABS(D10-E10)>$O$3,AND($O$11=1,B10<$O$12)),1,0) | I10: =IF(H10=1,NA(),D10) | J10: =IF(AND(ISNUMBER(D10),D10>=$O$4,OR($O$11=0,B10>=$O$12)),1,0) | K10: =B10-$O$14 | N10: En buyuk dusus (g) | O10: =MAX(G2:G503)
A11: 27 | B11: 0.9 | C11: 000 | D11: 0 | E11: =MEDIAN(D2:D31) | F11: =E11 | G11: =F11-E11 | H11: =IF(OR(NOT(ISNUMBER(D11)),ABS(D11-E11)>$O$3,AND($O$11=1,B11<$O$12)),1,0) | I11: =IF(H11=1,NA(),D11) | J11: =IF(AND(ISNUMBER(D11),D11>=$O$4,OR($O$11=0,B11>=$O$12)),1,0) | K11: =B11-$O$14 | N11: Reset tespit edildi mi (1/0) | O11: =IF(O10>$O$8,1,0)
A12: 30 | B12: 1 | C12: 000 | D12: 0 | E12: =MEDIAN(D2:D32) | F12: =E12 | G12: =F12-E12 | H12: =IF(OR(NOT(ISNUMBER(D12)),ABS(D12-E12)>$O$3,AND($O$11=1,B12<$O$12)),1,0) | I12: =IF(H12=1,NA(),D12) | J12: =IF(AND(ISNUMBER(D12),D12>=$O$4,OR($O$11=0,B12>=$O$12)),1,0) | K12: =B12-$O$14 | N12: Reset zamani (s) | O12: =IF(O11=1,INDEX(B2:B503,MATCH(O10,G2:G503,0)),-1000000)
A13: 33 | B13: 1.1 | C13: 00 | D13: 0 | E13: =MEDIAN(D2:D33) | F13: =E13 | G13: =F13-E13 | H13: =IF(OR(NOT(ISNUMBER(D13)),ABS(D13-E13)>$O$3,AND($O$11=1,B13<$O$12)),1,0) | I13: =IF(H13=1,NA(),D13) | J13: =IF(AND(ISNUMBER(D13),D13>=$O$4,OR($O$11=0,B13>=$O$12)),1,0) | K13: =B13-$O$14
A14: 36 | B14: 1.2 | C14: 00 | D14: 0 | E14: =MEDIAN(D2:D34) | F14: =E14 | G14: =F14-E14 | H14: =IF(OR(NOT(ISNUMBER(D14)),ABS(D14-E14)>$O$3,AND($O$11=1,B14<$O$12)),1,0) | I14: =IF(H14=1,NA(),D14) | J14: =IF(AND(ISNUMBER(D14),D14>=$O$4,OR($O$11=0,B14>=$O$12)),1,0) | K14: =B14-$O$14 | N14: Baslangic zamani (s) | O14: =INDEX(B2:B503,MATCH(1,J2:J503,0))
A15: 39 | B15: 1.3 | C15: 000 | D15: 0 | E15: =MEDIAN(D2:D35) | F15: =E15 | G15: =F15-E15 | H15: =IF(OR(NOT(ISNUMBER(D15)),ABS(D15-E15)>$O$3,AND($O$11=1,B15<$O$12)),1,0) | I15: =IF(H15=1,NA(),D15) | J15: =IF(AND(ISNUMBER(D15),D15>=$O$4,OR($O$11=0,B15>=$O$12)),1,0) | K15: =B15-$O$14
A16: 42 | B16: 1.4 | C16: 000 | D16: 0 | E16: =MEDIAN(D2:D36) | F16: =E16 | G16: =F16-E16 | H16: =IF(OR(NOT(ISNUMBER(D16)),ABS(D16-E16)>$O$3,AND($O$11=1,B16<$O$12)),1,0) | I16: =IF(H16=1,NA(),D16) | J16: =IF(AND(ISNUMBER(D16),D16>=$O$4,OR($O$11=0,B16>=$O$12)),1,0) | K16: =B16-$O$14
A17: 45 | B17: 1.5 | C17: 000 | D17: 0 | E17: =MEDIAN(D2:D37) | F17: =E17 | G17: =F17-E17 | H17: =IF(OR(NOT(ISNUMBER(D17)),ABS(D17-E17)>$O$3,AND($O$11=1,B17<$O$12)),1,0) | I17: =IF(H17=1,NA(),D17) | J17: =IF(AND(ISNUMBER(D17),D17>=$O$4,OR($O$11=0,B17>=$O$12)),1,0) | K17: =B17-$O$14
A18: 48 | B18: 1.6 | C18: 08 | D18: 0.08 | E18: =MEDIAN(D2:D38) | F18: =E18 | G18: =F18-E18 | H18: =IF(OR(NOT(ISNUMBER(D18)),ABS(D18-E18)>$O$3,AND($O$11=1,B18<$O$12)),1,0) | I18: =IF(H18=1,NA(),D18) | J18: =IF(AND(ISNUMBER(D18),D18>=$O$4,OR($O$11=0,B18>=$O$12)),1,0) | K18: =B18-$O$14
A19: 51 | B19: 1.7 | C19: 000 | D19: 0 | E19: =MEDIAN(D2:D39) | F19: =E19 | G19: =F19-E19 | H19: =IF(OR(NOT(ISNUMBER(D19)),ABS(D19-E19)>$O$3,AND($O$11=1,B19<$O$12)),1,0) | I19: =IF(H19=1,NA(),D19) | J19: =IF(AND(ISNUMBER(D19),D19>=$O$4,OR($O$11=0,B19>=$O$12)),1,0) | K19: =B19-$O$14
A20: 54 | B20: 1.8 | C20: 00 | D20: 0 | E20: =MEDIAN(D2:D40) | F20: =E20 | G20: =F20-E20 | H20: =IF(OR(NOT(ISNUMBER(D20)),ABS(D20-E20)>$O$3,AND($O$11=1,B20<$O$12)),1,0) | I20: =IF(H20=1,NA(),D20) | J20: =IF(AND(ISNUMBER(D20),D20>=$O$4,OR($O$11=0,B20>=$O$12)),1,0) | K20: =B20-$O$14
A21: 57 | B21: 1.9 | C21: 00 | D21: 0 | E21: =MEDIAN(D2:D41) | F21: =E21 | G21: =F21-E21 | H21: =IF(OR(NOT(ISNUMBER(D21)),ABS(D21-E21)>$O$3,AND($O$11=1,B21<$O$12)),1,0) | I21: =IF(H21=1,NA(),D21) | J21: =IF(AND(ISNUMBER(D21),D21>=$O$4,OR($O$11=0,B21>=$O$12)),1,0) | K21: =B21-$O$14
A22: 60 | B22: 2 | C22: 025 | D22: 0.25 | E22: =MEDIAN(D2:D42) | F22: =E2 | G22: =F22-E22 | H22: =IF(OR(NOT(ISNUMBER(D22)),ABS(D22-E22)>$O$3,AND($O$11=1,B22<$O$12)),1,0) | I22: =IF(H22=1,NA(),D22) | J22: =IF(AND(ISNUMBER(D22),D22>=$O$4,OR($O$11=0,B22>=$O$12)),1,0) | K22: =B22-$O$14
A23: 63 | B23: 2.1 | C23: 053 | D23: 0.53 | E23: =MEDIAN(D3:D43) | F23: =E3 | G23: =F23-E23 | H23: =IF(OR(NOT(ISNUMBER(D23)),ABS(D23-E23)>$O$3,AND($O$11=1,B23<$O$12)),1,0) | I23: =IF(H23=1,NA(),D23) | J23: =IF(AND(ISNUMBER(D23),D23>=$O$4,OR($O$11=0,B23>=$O$12)),1,0) | K23: =B23-$O$14
A24: 66 | B24: 2.2 | C24: 83 | D24: 0.83 | E24: =MEDIAN(D4:D44) | F24: =E4 | G24: =F24-E24 | H24: =IF(OR(NOT(ISNUMBER(D24)),ABS(D24-E24)>$O$3,AND($O$11=1,B24<$O$12)),1,0) | I24: =IF(H24=1,NA(),D24) | J24: =IF(AND(ISNUMBER(D24),D24>=$O$4,OR($O$11=0,B24>=$O$12)),1,0) | K24: =B24-$O$14
A25: 69 | B25: 2.3 | C25: 18 | D25: 0.18 | E25: =MEDIAN(D5:D45) | F25: =E5 | G25: =F25-E25 | H25: =IF(OR(NOT(ISNUMBER(D25)),ABS(D25-E25)>$O$3,AND($O$11=1,B25<$O$12)),1,0) | I25: =IF(H25=1,NA(),D25) | J25: =IF(AND(ISNUMBER(D25),D25>=$O$4,OR($O$11=0,B25>=$O$12)),1,0) | K25: =B25-$O$14
A26: 72 | B26: 2.4 | C26: 155 | D26: 1.55 | E26: =MEDIAN(D6:D46) | F26: =E6 | G26: =F26-E26 | H26: =IF(OR(NOT(ISNUMBER(D26)),ABS(D26-E26)>$O$3,AND($O$11=1,B26<$O$12)),1,0) | I26: =IF(H26=1,NA(),D26) | J26: =IF(AND(ISNUMBER(D26),D26>=$O$4,OR($O$11=0,B26>=$O$12)),1,0) | K26: =B26-$O$14
A27: 75 | B27: 2.5 | C27: ?06 | E27: =MEDIAN(D7:D47) | F27: =E7 | G27: =F27-E27 | H27: =IF(OR(NOT(ISNUMBER(D27)),ABS(D27-E27)>$O$3,AND($O$11=1,B27<$O$12)),1,0) | I27: =IF(H27=1,NA(),D27) | J27: =IF(AND(ISNUMBER(D27),D27>=$O$4,OR($O$11=0,B27>=$O$12)),1,0) | K27: =B27-$O$14
A28: 78 | B28: 2.6 | C28: 255 | D28: 2.55 | E28: =MEDIAN(D8:D48) | F28: =E8 | G28: =F28-E28 | H28: =IF(OR(NOT(ISNUMBER(D28)),ABS(D28-E28)>$O$3,AND($O$11=1,B28<$O$12)),1,0) | I28: =IF(H28=1,NA(),D28) | J28: =IF(AND(ISNUMBER(D28),D28>=$O$4,OR($O$11=0,B28>=$O$12)),1,0) | K28: =B28-$O$14
A29: 81 | B29: 2.7 | C29: 317 | D29: 3.17 | E29: =MEDIAN(D9:D49) | F29: =E9 | G29: =F29-E29 | H29: =IF(OR(NOT(ISNUMBER(D29)),ABS(D29-E29)>$O$3,AND($O$11=1,B29<$O$12)),1,0) | I29: =IF(H29=1,NA(),D29) | J29: =IF(AND(ISNUMBER(D29),D29>=$O$4,OR($O$11=0,B29>=$O$12)),1,0) | K29: =B29-$O$14
A30: 84 | B30: 2.8 | C30: 390 | D30: 3.9 | E30: =MEDIAN(D10:D50) | F30: =E10 | G30: =F30-E30 | H30: =IF(OR(NOT(ISNUMBER(D30)),ABS(D30-E30)>$O$3,AND($O$11=1,B30<$O$12)),1,0) | I30: =IF(H30=1,NA(),D30) | J30: =IF(AND(ISNUMBER(D30),D30>=$O$4,OR($O$11=0,B30>=$O$12)),1,0) | K30: =B30-$O$14
A31: 87 | B31: 2.9 | C31: 446 | D31: 4.46 | E31: =MEDIAN(D11:D51) | F31: =E11 | G31: =F31-E31 | H31: =IF(OR(NOT(ISNUMBER(D31)),ABS(D31-E31)>$O$3,AND($O$11=1,B31<$O$12)),1,0) | I31: =IF(H31=1,NA(),D31) | J31: =IF(AND(ISNUMBER(D31),D31>=$O$4,OR($O$11=0,B31>=$O$12)),1,0) | K31: =B31-$O$14
A32: 90 | B32: 3 | C32: 512 | D32: 5.12 | E32: =MEDIAN(D12:D52) | F32: =E12 | G32: =F32-E32 | H32: =IF(OR(NOT(ISNUMBER(D32)),ABS(D32-E32)>$O$3,AND($O$11=1,B32<$O$12)),1,0) | I32: =IF(H32=1,NA(),D32) | J32: =IF(AND(ISNUMBER(D32),D32>=$O$4,OR($O$11=0,B32>=$O$12)),1,0) | K32: =B32-$O$14
A33: 93 | B33: 3.1 | C33: 75 | D33: 0.75 | E33: =MEDIAN(D13:D53) | F33: =E13 | G33: =F33-E33 | H33: =IF(OR(NOT(ISNUMBER(D33)),ABS(D33-E33)>$O$3,AND($O$11=1,B33<$O$12)),1,0) | I33: =IF(H33=1,NA(),D33) | J33: =IF(AND(ISNUMBER(D33),D33>=$O$4,OR($O$11=0,B33>=$O$12)),1,0) | K33: =B33-$O$14
A34: 96 | B34: 3.2 | C34: 35 | D34: 0.35 | E34: =MEDIAN(D14:D54) | F34: =E14 | G34: =F34-E34 | H34: =IF(OR(NOT(ISNUMBER(D34)),ABS(D34-E34)>$O$3,AND($O$11=1,B34<$O$12)),1,0) | I34: =IF(H34=1,NA(),D34) | J34: =IF(AND(ISNUMBER(D34),D34>=$O$4,OR($O$11=0,B34>=$O$12)),1,0) | K34: =B34-$O$14
A35: 99 | B35: 3.3 | C35: 696 | D35: 6.96 | E35: =MEDIAN(D15:D55) | F35: =E15 | G35: =F35-E35 | H35: =IF(OR(NOT(ISNUMBER(D35)),ABS(D35-E35)>$O$3,AND($O$11=1,B35<$O$12)),1,0) | I35: =IF(H35=1,NA(),D35) | J35: =IF(AND(ISNUMBER(D35),D35>=$O$4,OR($O$11=0,B35>=$O$12)),1,0) | K35: =B35-$O$14
A36: 102 | B36: 3.4 | C36: ?56 | E36: =MEDIAN(D16:D56) | F36: =E16 | G36: =F36-E36 | H36: =IF(OR(NOT(ISNUMBER(D36)),ABS(D36-E36)>$O$3,AND($O$11=1,B36<$O$12)),1,0) | I36: =IF(H36=1,NA(),D36) | J36: =IF(AND(ISNUMBER(D36),D36>=$O$4,OR($O$11=0,B36>=$O$12)),1,0) | K36: =B36-$O$14
A37: 105 | B37: 3.5 | C37: 816 | D37: 8.16 | E37: =MEDIAN(D17:D57) | F37: =E17 | G37: =F37-E37 | H37: =IF(OR(NOT(ISNUMBER(D37)),ABS(D37-E37)>$O$3,AND($O$11=1,B37<$O$12)),1,0) | I37: =IF(H37=1,NA(),D37) | J37: =IF(AND(ISNUMBER(D37),D37>=$O$4,OR($O$11=0,B37>=$O$12)),1,0) | K37: =B37-$O$14
A38: 108 | B38: 3.6 | C38: 75 | D38: 0.75 | E38: =MEDIAN(D18:D58) | F38: =E18 | G38: =F38-E38 | H38: =IF(OR(NOT(ISNUMBER(D38)),ABS(D38-E38)>$O$3,AND($O$11=1,B38<$O$12)),1,0) | I38: =IF(H38=1,NA(),D38) | J38: =IF(AND(ISNUMBER(D38),D38>=$O$4,OR($O$11=0,B38>=$O$12)),1,0) | K38: =B38-$O$14
A39: 111 | B39: 3.7 | C39: 33 | D39: 0.33 | E39: =MEDIAN(D19:D59) | F39: =E19 | G39: =F39-E39 | H39: =IF(OR(NOT(ISNUMBER(D39)),ABS(D39-E39)>$O$3,AND($O$11=1,B39<$O$12)),1,0) | I39: =IF(H39=1,NA(),D39) | J39: =IF(AND(ISNUMBER(D39),D39>=$O$4,OR($O$11=0,B39>=$O$12)),1,0) | K39: =B39-$O$14
A40: 114 | B40: 3.8 | C40: 95 | D40: 0.95 | E40: =MEDIAN(D20:D60) | F40: =E20 | G40: =F40-E40 | H40: =IF(OR(NOT(ISNUMBER(D40)),ABS(D40-E40)>$O$3,AND($O$11=1,B40<$O$12)),1,0) | I40: =IF(H40=1,NA(),D40) | J40: =IF(AND(ISNUMBER(D40),D40>=$O$4,OR($O$11=0,B40>=$O$12)),1,0) | K40: =B40-$O$14
...

Sheet Hacim
A1: time_corrected_s | B1: remaining_volume_mL
A2: =Sheet1!K2 | B2: =IF(ISNA(Sheet1!I2),NA(),Sheet1!$O$5-(Sheet1!I2/Sheet1!$O$6))
A3: =Sheet1!K3 | B3: =IF(ISNA(Sheet1!I3),NA(),Sheet1!$O$5-(Sheet1!I3/Sheet1!$O$6))
A4: =Sheet1!K4 | B4: =IF(ISNA(Sheet1!I4),NA(),Sheet1!$O$5-(Sheet1!I4/Sheet1!$O$6))
A5: =Sheet1!K5 | B5: =IF(ISNA(Sheet1!I5),NA(),Sheet1!$O$5-(Sheet1!I5/Sheet1!$O$6))
A6: =Sheet1!K6 | B6: =IF(ISNA(Sheet1!I6),NA(),Sheet1!$O$5-(Sheet1!I6/Sheet1!$O$6))
A7: =Sheet1!K7 | B7: =IF(ISNA(Sheet1!I7),NA(),Sheet1!$O$5-(Sheet1!I7/Sheet1!$O$6))
A8: =Sheet1!K8 | B8: =IF(ISNA(Sheet1!I8),NA(),Sheet1!$O$5-(Sheet1!I8/Sheet1!$O$6))
A9: =Sheet1!K9 | B9: =IF(ISNA(Sheet1!I9),NA(),Sheet1!$O$5-(Sheet1!I9/Sheet1!$O$6))
A10: =Sheet1!K10 | B10: =IF(ISNA(Sheet1!I10),NA(),Sheet1!$O$5-(Sheet1!I10/Sheet1!$O$6))
A11: =Sheet1!K11 | B11: =IF(ISNA(Sheet1!I11),NA(),Sheet1!$O$5-(Sheet1!I11/Sheet1!$O$6))
A12: =Sheet1!K12 | B12: =IF(ISNA(Sheet1!I12),NA(),Sheet1!$O$5-(Sheet1!I12/Sheet1!$O$6))
A13: =Sheet1!K13 | B13: =IF(ISNA(Sheet1!I13),NA(),Sheet1!$O$5-(Sheet1!I13/Sheet1!$O$6))
... A503: =Sheet1!K503 | B503: =IF(ISNA(Sheet1!I503),NA(),Sheet1!$O$5-(Sheet1!I503/Sheet1!$O$6))
