Workbook

Sheet Sheet1
A1: frame_no | B1: timestamp_sec | C1: raw_digits | D1: weight | E1: is_started | F1: time_corrected_s | N1: Parametreler
A2: 0 | B2: 0 | C2: 1157 | D2: 11.57 | E2: =IF(AND(ISNUMBER(D2),D2>=$O$4),1,0) | F2: =B2-$O$8 | N2: Medyan penceresi (satir, her yonde) | O2: 20
A3: 3 | B3: 0.1 | C3: 1107 | D3: 11.07 | E3: =IF(AND(ISNUMBER(D3),D3>=$O$4),1,0) | F3: =B3-$O$8 | N3: Disleme toleransi (g) | O3: 0.15
A4: 6 | B4: 0.2 | C4: 1157 | D4: 11.57 | E4: =IF(AND(ISNUMBER(D4),D4>=$O$4),1,0) | F4: =B4-$O$8 | N4: Baslangic esigi (g) | O4: 0.05
A5: 9 | B5: 0.3 | C5: 1157 | D5: 11.57 | E5: =IF(AND(ISNUMBER(D5),D5>=$O$4),1,0) | F5: =B5-$O$8 | N5: Siringa hacmi (mL) | O5: 10
A6: 12 | B6: 0.4 | C6: 1157 | D6: 11.57 | E6: =IF(AND(ISNUMBER(D6),D6>=$O$4),1,0) | F6: =B6-$O$8 | N6: Yogunluk (g/mL) | O6: 1
A7: 15 | B7: 0.5 | C7: 1157 | D7: 11.57 | E7: =IF(AND(ISNUMBER(D7),D7>=$O$4),1,0) | F7: =B7-$O$8
A8: 18 | B8: 0.6 | C8: 1157 | D8: 11.57 | E8: =IF(AND(ISNUMBER(D8),D8>=$O$4),1,0) | F8: =B8-$O$8 | N8: Baslangic zamani (s) | O8: =IFERROR(INDEX(B2:B1807,MATCH(1,E2:E1807,0)),0)
A9: 21 | B9: 0.7 | C9: 1157 | D9: 11.57 | E9: =IF(AND(ISNUMBER(D9),D9>=$O$4),1,0) | F9: =B9-$O$8
A10: 24 | B10: 0.8 | C10: 1157 | D10: 11.57 | E10: =IF(AND(ISNUMBER(D10),D10>=$O$4),1,0) | F10: =B10-$O$8
A11: 27 | B11: 0.9 | C11: 1157 | D11: 11.57 | E11: =IF(AND(ISNUMBER(D11),D11>=$O$4),1,0) | F11: =B11-$O$8
A12: 30 | B12: 1 | C12: 1157 | D12: 11.57 | E12: =IF(AND(ISNUMBER(D12),D12>=$O$4),1,0) | F12: =B12-$O$8
A13: 33 | B13: 1.1 | C13: 1157 | D13: 11.57 | E13: =IF(AND(ISNUMBER(D13),D13>=$O$4),1,0) | F13: =B13-$O$8
A14: 36 | B14: 1.2 | C14: 1157 | D14: 11.57 | E14: =IF(AND(ISNUMBER(D14),D14>=$O$4),1,0) | F14: =B14-$O$8
A15: 39 | B15: 1.3 | C15: 1157 | D15: 11.57 | E15: =IF(AND(ISNUMBER(D15),D15>=$O$4),1,0) | F15: =B15-$O$8
A16: 42 | B16: 1.4 | C16: 1107 | D16: 11.07 | E16: =IF(AND(ISNUMBER(D16),D16>=$O$4),1,0) | F16: =B16-$O$8
A17: 45 | B17: 1.5 | C17: 1157 | D17: 11.57 | E17: =IF(AND(ISNUMBER(D17),D17>=$O$4),1,0) | F17: =B17-$O$8
A18: 48 | B18: 1.6 | C18: 1157 | D18: 11.57 | E18: =IF(AND(ISNUMBER(D18),D18>=$O$4),1,0) | F18: =B18-$O$8
A19: 51 | B19: 1.7 | C19: 1157 | D19: 11.57 | E19: =IF(AND(ISNUMBER(D19),D19>=$O$4),1,0) | F19: =B19-$O$8
A20: 54 | B20: 1.8 | C20: 1157 | D20: 11.57 | E20: =IF(AND(ISNUMBER(D20),D20>=$O$4),1,0) | F20: =B20-$O$8
... A52: 150 | B52: 5 | C52: 055 | D52: 0.55 | E52: =IF(AND(ISNUMBER(D52),D52>=$O$4),1,0) | F52: =B52-$O$8
A53: 153 | B53: 5.1 | C53: 05? | E53: =IF(AND(ISNUMBER(D53),D53>=$O$4),1,0) | F53: =B53-$O$8
A54: 156 | B54: 5.2 | C54: 05? | E54: =IF(AND(ISNUMBER(D54),D54>=$O$4),1,0) | F54: =B54-$O$8
A55: 159 | B55: 5.3 | C55: 053 | D55: 0.53 | E55: =IF(AND(ISNUMBER(D55),D55>=$O$4),1,0) | F55: =B55-$O$8
A56: 162 | B56: 5.4 | C56: 055 | D56: 0.55 | E56: =IF(AND(ISNUMBER(D56),D56>=$O$4),1,0) | F56: =B56-$O$8
A57: 165 | B57: 5.5 | C57: 055 | D57: 0.55 | E57: =IF(AND(ISNUMBER(D57),D57>=$O$4),1,0) | F57: =B57-$O$8
A58: 168 | B58: 5.6 | C58: 055 | D58: 0.55 | E58: =IF(AND(ISNUMBER(D58),D58>=$O$4),1,0) | F58: =B58-$O$8
A59: 171 | B59: 5.7 | C59: 0?3 | E59: =IF(AND(ISNUMBER(D59),D59>=$O$4),1,0) | F59: =B59-$O$8
A60: 174 | B60: 5.8 | C60: 023 | D60: 0.23 | E60: =IF(AND(ISNUMBER(D60),D60>=$O$4),1,0) | F60: =B60-$O$8
A61: 177 | B61: 5.9 | C61: 024 | D61: 0.24 | E61: =IF(AND(ISNUMBER(D61),D61>=$O$4),1,0) | F61: =B61-$O$8
A62: 180 | B62: 6 | C62: 024 | D62: 0.24 | E62: =IF(AND(ISNUMBER(D62),D62>=$O$4),1,0) | F62: =B62-$O$8
A63: 183 | B63: 6.1 | C63: 025 | D63: 0.25 | E63: =IF(AND(ISNUMBER(D63),D63>=$O$4),1,0) | F63: =B63-$O$8
A64: 186 | B64: 6.2 | C64: 027 | D64: 0.27 | E64: =IF(AND(ISNUMBER(D64),D64>=$O$4),1,0) | F64: =B64-$O$8
A65: 189 | B65: 6.3 | C65: 025 | D65: 0.25 | E65: =IF(AND(ISNUMBER(D65),D65>=$O$4),1,0) | F65: =B65-$O$8
A66: 192 | B66: 6.4 | C66: 030 | D66: 0.3 | E66: =IF(AND(ISNUMBER(D66),D66>=$O$4),1,0) | F66: =B66-$O$8
A67: 195 | B67: 6.5 | C67: 032 | D67: 0.32 | E67: =IF(AND(ISNUMBER(D67),D67>=$O$4),1,0) | F67: =B67-$O$8
A68: 198 | B68: 6.6 | C68: 034 | D68: 0.34 | E68: =IF(AND(ISNUMBER(D68),D68>=$O$4),1,0) | F68: =B68-$O$8
A69: 201 | B69: 6.7 | C69: 037 | D69: 0.37 | E69: =IF(AND(ISNUMBER(D69),D69>=$O$4),1,0) | F69: =B69-$O$8
A70: 204 | B70: 6.8 | C70: 035 | D70: 0.35 | E70: =IF(AND(ISNUMBER(D70),D70>=$O$4),1,0) | F70: =B70-$O$8
A71: 207 | B71: 6.9 | C71: 04? | E71: =IF(AND(ISNUMBER(D71),D71>=$O$4),1,0) | F71: =B71-$O$8
...

Sheet Hacim
A1: time_corrected_s | B1: remaining_volume_mL
A2: =Sheet1!F2 | B2: =IF(NOT(ISNUMBER(Sheet1!D2)),NA(),Sheet1!$O$5-(Sheet1!D2/Sheet1!$O$6))
A3: =Sheet1!F3 | B3: =IF(NOT(ISNUMBER(Sheet1!D3)),NA(),Sheet1!$O$5-(Sheet1!D3/Sheet1!$O$6))
A4: =Sheet1!F4 | B4: =IF(NOT(ISNUMBER(Sheet1!D4)),NA(),Sheet1!$O$5-(Sheet1!D4/Sheet1!$O$6))
A5: =Sheet1!F5 | B5: =IF(NOT(ISNUMBER(Sheet1!D5)),NA(),Sheet1!$O$5-(Sheet1!D5/Sheet1!$O$6))
A6: =Sheet1!F6 | B6: =IF(NOT(ISNUMBER(Sheet1!D6)),NA(),Sheet1!$O$5-(Sheet1!D6/Sheet1!$O$6))
A7: =Sheet1!F7 | B7: =IF(NOT(ISNUMBER(Sheet1!D7)),NA(),Sheet1!$O$5-(Sheet1!D7/Sheet1!$O$6))
A8: =Sheet1!F8 | B8: =IF(NOT(ISNUMBER(Sheet1!D8)),NA(),Sheet1!$O$5-(Sheet1!D8/Sheet1!$O$6))
A9: =Sheet1!F9 | B9: =IF(NOT(ISNUMBER(Sheet1!D9)),NA(),Sheet1!$O$5-(Sheet1!D9/Sheet1!$O$6))
A10: =Sheet1!F10 | B10: =IF(NOT(ISNUMBER(Sheet1!D10)),NA(),Sheet1!$O$5-(Sheet1!D10/Sheet1!$O$6))
A11: =Sheet1!F11 | B11: =IF(NOT(ISNUMBER(Sheet1!D11)),NA(),Sheet1!$O$5-(Sheet1!D11/Sheet1!$O$6))
A12: =Sheet1!F12 | B12: =IF(NOT(ISNUMBER(Sheet1!D12)),NA(),Sheet1!$O$5-(Sheet1!D12/Sheet1!$O$6))
A13: =Sheet1!F13 | B13: =IF(NOT(ISNUMBER(Sheet1!D13)),NA(),Sheet1!$O$5-(Sheet1!D13/Sheet1!$O$6))
... A1807: =Sheet1!F1807 | B1807: =IF(NOT(ISNUMBER(Sheet1!D1807)),NA(),Sheet1!$O$5-(Sheet1!D1807/Sheet1!$O$6))
