Workbook

Sheet Sheet1
A1: frame_no | B1: timestamp_sec | C1: raw_digits | D1: weight | E1: local_median_g | F1: excluded | G1: weight_kept_g | H1: is_started | I1: time_corrected_s | N1: Parametreler
A2: 0 | B2: 0 | C2: 000 | D2: 0 | E2: =IFERROR(MEDIAN(D2:D22),D2) | F2: =IF(OR(NOT(ISNUMBER(D2)),ABS(D2-E2)>$O$3),1,0) | G2: =IF(F2=1,NA(),D2) | H2: =IF(AND(ISNUMBER(D2),D2>=$O$4),1,0) | I2: =B2-$O$8 | N2: Medyan penceresi (satir, her yonde) | O2: 20
A3: 3 | B3: 0.1 | C3: 000 | D3: 0 | E3: =IFERROR(MEDIAN(D2:D23),D3) | F3: =IF(OR(NOT(ISNUMBER(D3)),ABS(D3-E3)>$O$3),1,0) | G3: =IF(F3=1,NA(),D3) | H3: =IF(AND(ISNUMBER(D3),D3>=$O$4),1,0) | I3: =B3-$O$8 | N3: Disleme toleransi (g) | O3: 0.15
A4: 6 | B4: 0.2 | C4: 000 | D4: 0 | E4: =IFERROR(MEDIAN(D2:D24),D4) | F4: =IF(OR(NOT(ISNUMBER(D4)),ABS(D4-E4)>$O$3),1,0) | G4: =IF(F4=1,NA(),D4) | H4: =IF(AND(ISNUMBER(D4),D4>=$O$4),1,0) | I4: =B4-$O$8 | N4: Baslangic esigi (g) | O4: 0.05
A5: 9 | B5: 0.3 | C5: 000 | D5: 0 | E5: =IFERROR(MEDIAN(D2:D25),D5) | F5: =IF(OR(NOT(ISNUMBER(D5)),ABS(D5-E5)>$O$3),1,0) | G5: =IF(F5=1,NA(),D5) | H5: =IF(AND(ISNUMBER(D5),D5>=$O$4),1,0) | I5: =B5-$O$8 | N5: Siringa hacmi (mL) | O5: 10
A6: 12 | B6: 0.4 | C6: 000 | D6: 0 | E6: =IFERROR(MEDIAN(D2:D26),D6) | F6: =IF(OR(NOT(ISNUMBER(D6)),ABS(D6-E6)>$O$3),1,0) | G6: =IF(F6=1,NA(),D6) | H6: =IF(AND(ISNUMBER(D6),D6>=$O$4),1,0) | I6: =B6-$O$8 | N6: Yogunluk (g/mL) | O6: 1
A7: 15 | B7: 0.5 | C7: 000 | D7: 0 | E7: =IFERROR(MEDIAN(D2:D27),D7) | F7: =IF(OR(NOT(ISNUMBER(D7)),ABS(D7-E7)>$O$3),1,0) | G7: =IF(F7=1,NA(),D7) | H7: =IF(AND(ISNUMBER(D7),D7>=$O$4),1,0) | I7: =B7-$O$8
A8: 18 | B8: 0.6 | C8: 000 | D8: 0 | E8: =IFERROR(MEDIAN(D2:D28),D8) | F8: =IF(OR(NOT(ISNUMBER(D8)),ABS(D8-E8)>$O$3),1,0) | G8: =IF(F8=1,NA(),D8) | H8: =IF(AND(ISNUMBER(D8),D8>=$O$4),1,0) | I8: =B8-$O$8 | N8: Baslangic zamani (s) | O8: =IFERROR(INDEX(B2:B302,MATCH(1,H2:H302,0)),0)
A9: 21 | B9: 0.7 | C9: 000 | D9: 0 | E9: =IFERROR(MEDIAN(D2:D29),D9) | F9: =IF(OR(NOT(ISNUMBER(D9)),ABS(D9-E9)>$O$3),1,0) | G9: =IF(F9=1,NA(),D9) | H9: =IF(AND(ISNUMBER(D9),D9>=$O$4),1,0) | I9: =B9-$O$8
A10: 24 | B10: 0.8 | C10: 000 | D10: 0 | E10: =IFERROR(MEDIAN(D2:D30),D10) | F10: =IF(OR(NOT(ISNUMBER(D10)),ABS(D10-E10)>$O$3),1,0) | G10: =IF(F10=1,NA(),D10) | H10: =IF(AND(ISNUMBER(D10),D10>=$O$4),1,0) | I10: =B10-$O$8
A11: 27 | B11: 0.9 | C11: 000 | D11: 0 | E11: =IFERROR(MEDIAN(D2:D31),D11) | F11: =IF(OR(NOT(ISNUMBER(D11)),ABS(D11-E11)>$O$3),1,0) | G11: =IF(F11=1,NA(),D11) | H11: =IF(AND(ISNUMBER(D11),D11>=$O$4),1,0) | I11: =B11-$O$8
A12: 30 | B12: 1 | C12: 000 | D12: 0 | E12: =IFERROR(MEDIAN(D2:D32),D12) | F12: =IF(OR(NOT(ISNUMBER(D12)),ABS(D12-E12)>$O$3),1,0) | G12: =IF(F12=1,NA(),D12) | H12: =IF(AND(ISNUMBER(D12),D12>=$O$4),1,0) | I12: =B12-$O$8
A13: 33 | B13: 1.1 | C13: 000 | D13: 0 | E13: =IFERROR(MEDIAN(D2:D33),D13) | F13: =IF(OR(NOT(ISNUMBER(D13)),ABS(D13-E13)>$O$3),1,0) | G13: =IF(F13=1,NA(),D13) | H13: =IF(AND(ISNUMBER(D13),D13>=$O$4),1,0) | I13: =B13-$O$8
A14: 36 | B14: 1.2 | C14: 000 | D14: 0 | E14: =IFERROR(MEDIAN(D2:D34),D14) | F14: =IF(OR(NOT(ISNUMBER(D14)),ABS(D14-E14)>$O$3),1,0) | G14: =IF(F14=1,NA(),D14) | H14: =IF(AND(ISNUMBER(D14),D14>=$O$4),1,0) | I14: =B14-$O$8
A15: 39 | B15: 1.3 | C15: 008 | D15: 0.08 | E15: =IFERROR(MEDIAN(D2:D35),D15) | F15: =IF(OR(NOT(ISNUMBER(D15)),ABS(D15-E15)>$O$3),1,0) | G15: =IF(F15=1,NA(),D15) | H15: =IF(AND(ISNUMBER(D15),D15>=$O$4),1,0) | I15: =B15-$O$8
A16: 42 | B16: 1.4 | C16: 015 | D16: 0.15 | E16: =IFERROR(MEDIAN(D2:D36),D16) | F16: =IF(OR(NOT(ISNUMBER(D16)),ABS(D16-E16)>$O$3),1,0) | G16: =IF(F16=1,NA(),D16) | H16: =IF(AND(ISNUMBER(D16),D16>=$O$4),1,0) | I16: =B16-$O$8
A17: 45 | B17: 1.5 | C17: 035 | D17: 0.35 | E17: =IFERROR(MEDIAN(D2:D37),D17) | F17: =IF(OR(NOT(ISNUMBER(D17)),ABS(D17-E17)>$O$3),1,0) | G17: =IF(F17=1,NA(),D17) | H17: =IF(AND(ISNUMBER(D17),D17>=$O$4),1,0) | I17: =B17-$O$8
A18: 48 | B18: 1.6 | C18: 035 | D18: 0.35 | E18: =IFERROR(MEDIAN(D2:D38),D18) | F18: =IF(OR(NOT(ISNUMBER(D18)),ABS(D18-E18)>$O$3),1,0) | G18: =IF(F18=1,NA(),D18) | H18: =IF(AND(ISNUMBER(D18),D18>=$O$4),1,0) | I18: =B18-$O$8
A19: 51 | B19: 1.7 | C19: 088 | D19: 0.88 | E19: =IFERROR(MEDIAN(D2:D39),D19) | F19: =IF(OR(NOT(ISNUMBER(D19)),ABS(D19-E19)>$O$3),1,0) | G19: =IF(F19=1,NA(),D19) | H19: =IF(AND(ISNUMBER(D19),D19>=$O$4),1,0) | I19: =B19-$O$8
A20: 54 | B20: 1.8 | C20: 086 | D20: 0.86 | E20: =IFERROR(MEDIAN(D2:D40),D20) | F20: =IF(OR(NOT(ISNUMBER(D20)),ABS(D20-E20)>$O$3),1,0) | G20: =IF(F20=1,NA(),D20) | H20: =IF(AND(ISNUMBER(D20),D20>=$O$4),1,0) | I20: =B20-$O$8
A21: 57 | B21: 1.9 | C21: 098 | D21: 0.98 | E21: =IFERROR(MEDIAN(D2:D41),D21) | F21: =IF(OR(NOT(ISNUMBER(D21)),ABS(D21-E21)>$O$3),1,0) | G21: =IF(F21=1,NA(),D21) | H21: =IF(AND(ISNUMBER(D21),D21>=$O$4),1,0) | I21: =B21-$O$8
A22: 60 | B22: 2 | C22: 096 | D22: 0.96 | E22: =IFERROR(MEDIAN(D2:D42),D22) | F22: =IF(OR(NOT(ISNUMBER(D22)),ABS(D22-E22)>$O$3),1,0) | G22: =IF(F22=1,NA(),D22) | H22: =IF(AND(ISNUMBER(D22),D22>=$O$4),1,0) | I22: =B22-$O$8
A23: 63 | B23: 2.1 | C23: 36 | D23: 0.36 | E23: =IFERROR(MEDIAN(D3:D43),D23) | F23: =IF(OR(NOT(ISNUMBER(D23)),ABS(D23-E23)>$O$3),1,0) | G23: =IF(F23=1,NA(),D23) | H23: =IF(AND(ISNUMBER(D23),D23>=$O$4),1,0) | I23: =B23-$O$8
A24: 66 | B24: 2.2 | C24: 92 | D24: 0.92 | E24: =IFERROR(MEDIAN(D4:D44),D24) | F24: =IF(OR(NOT(ISNUMBER(D24)),ABS(D24-E24)>$O$3),1,0) | G24: =IF(F24=1,NA(),D24) | H24: =IF(AND(ISNUMBER(D24),D24>=$O$4),1,0) | I24: =B24-$O$8
A25: 69 | B25: 2.3 | C25: 98 | D25: 0.98 | E25: =IFERROR(MEDIAN(D5:D45),D25) | F25: =IF(OR(NOT(ISNUMBER(D25)),ABS(D25-E25)>$O$3),1,0) | G25: =IF(F25=1,NA(),D25) | H25: =IF(AND(ISNUMBER(D25),D25>=$O$4),1,0) | I25: =B25-$O$8
A26: 72 | B26: 2.4 | C26: 88 | D26: 0.88 | E26: =IFERROR(MEDIAN(D6:D46),D26) | F26: =IF(OR(NOT(ISNUMBER(D26)),ABS(D26-E26)>$O$3),1,0) | G26: =IF(F26=1,NA(),D26) | H26: =IF(AND(ISNUMBER(D26),D26>=$O$4),1,0) | I26: =B26-$O$8
A27: 75 | B27: 2.5 | C27: 86 | D27: 0.86 | E27: =IFERROR(MEDIAN(D7:D47),D27) | F27: =IF(OR(NOT(ISNUMBER(D27)),ABS(D27-E27)>$O$3),1,0) | G27: =IF(F27=1,NA(),D27) | H27: =IF(AND(ISNUMBER(D27),D27>=$O$4),1,0) | I27: =B27-$O$8
A28: 78 | B28: 2.6 | C28: 88 | D28: 0.88 | E28: =IFERROR(MEDIAN(D8:D48),D28) | F28: =IF(OR(NOT(ISNUMBER(D28)),ABS(D28-E28)>$O$3),1,0) | G28: =IF(F28=1,NA(),D28) | H28: =IF(AND(ISNUMBER(D28),D28>=$O$4),1,0) | I28: =B28-$O$8
A29: 81 | B29: 2.7 | C29: 88 | D29: 0.88 | E29: =IFERROR(MEDIAN(D9:D49),D29) | F29: =IF(OR(NOT(ISNUMBER(D29)),ABS(D29-E29)>$O$3),1,0) | G29: =IF(F29=1,NA(),D29) | H29: =IF(AND(ISNUMBER(D29),D29>=$O$4),1,0) | I29: =B29-$O$8
A30: 84 | B30: 2.8 | C30: 96 | D30: 0.96 | E30: =IFERROR(MEDIAN(D10:D50),D30) | F30: =IF(OR(NOT(ISNUMBER(D30)),ABS(D30-E30)>$O$3),1,0) | G30: =IF(F30=1,NA(),D30) | H30: =IF(AND(ISNUMBER(D30),D30>=$O$4),1,0) | I30: =B30-$O$8
A31: 87 | B31: 2.9 | C31: 08 | D31: 0.08 | E31: =IFERROR(MEDIAN(D11:D51),D31) | F31: =IF(OR(NOT(ISNUMBER(D31)),ABS(D31-E31)>$O$3),1,0) | G31: =IF(F31=1,NA(),D31) | H31: =IF(AND(ISNUMBER(D31),D31>=$O$4),1,0) | I31: =B31-$O$8
A32: 90 | B32: 3 | C32: 89 | D32: 0.89 | E32: =IFERROR(MEDIAN(D12:D52),D32) | F32: =IF(OR(NOT(ISNUMBER(D32)),ABS(D32-E32)>$O$3),1,0) | G32: =IF(F32=1,NA(),D32) | H32: =IF(AND(ISNUMBER(D32),D32>=$O$4),1,0) | I32: =B32-$O$8
A33: 93 | B33: 3.1 | C33: 05 | D33: 0.05 | E33: =IFERROR(MEDIAN(D13:D53),D33) | F33: =IF(OR(NOT(ISNUMBER(D33)),ABS(D33-E33)>$O$3),1,0) | G33: =IF(F33=1,NA(),D33) | H33: =IF(AND(ISNUMBER(D33),D33>=$O$4),1,0) | I33: =B33-$O$8
... A37: 105 | B37: 3.5 | C37: 66 | D37: 0.66 | E37: =IFERROR(MEDIAN(D17:D57),D37) | F37: =IF(OR(NOT(ISNUMBER(D37)),ABS(D37-E37)>$O$3),1,0) | G37: =IF(F37=1,NA(),D37) | H37: =IF(AND(ISNUMBER(D37),D37>=$O$4),1,0) | I37: =B37-$O$8
A38: 108 | B38: 3.6 | C38: 8?1 | E38: =IFERROR(MEDIAN(D18:D58),D38) | F38: =IF(OR(NOT(ISNUMBER(D38)),ABS(D38-E38)>$O$3),1,0) | G38: =IF(F38=1,NA(),D38) | H38: =IF(AND(ISNUMBER(D38),D38>=$O$4),1,0) | I38: =B38-$O$8
A39: 111 | B39: 3.7 | C39: 86 | D39: 0.86 | E39: =IFERROR(MEDIAN(D19:D59),D39) | F39: =IF(OR(NOT(ISNUMBER(D39)),ABS(D39-E39)>$O$3),1,0) | G39: =IF(F39=1,NA(),D39) | H39: =IF(AND(ISNUMBER(D39),D39>=$O$4),1,0) | I39: =B39-$O$8
A40: 114 | B40: 3.8 | C40: 408 | D40: 4.08 | E40: =IFERROR(MEDIAN(D20:D60),D40) | F40: =IF(OR(NOT(ISNUMBER(D40)),ABS(D40-E40)>$O$3),1,0) | G40: =IF(F40=1,NA(),D40) | H40: =IF(AND(ISNUMBER(D40),D40>=$O$4),1,0) | I40: =B40-$O$8
A41: 117 | B41: 3.9 | C41: 408 | D41: 4.08 | E41: =IFERROR(MEDIAN(D21:D61),D41) | F41: =IF(OR(NOT(ISNUMBER(D41)),ABS(D41-E41)>$O$3),1,0) | G41: =IF(F41=1,NA(),D41) | H41: =IF(AND(ISNUMBER(D41),D41>=$O$4),1,0) | I41: =B41-$O$8
A42: 120 | B42: 4 | C42: 436 | D42: 4.36 | E42: =IFERROR(MEDIAN(D22:D62),D42) | F42: =IF(OR(NOT(ISNUMBER(D42)),ABS(D42-E42)>$O$3),1,0) | G42: =IF(F42=1,NA(),D42) | H42: =IF(AND(ISNUMBER(D42),D42>=$O$4),1,0) | I42: =B42-$O$8
A43: 123 | B43: 4.1 | C43: 438 | D43: 4.38 | E43: =IFERROR(MEDIAN(D23:D63),D43) | F43: =IF(OR(NOT(ISNUMBER(D43)),ABS(D43-E43)>$O$3),1,0) | G43: =IF(F43=1,NA(),D43) | H43: =IF(AND(ISNUMBER(D43),D43>=$O$4),1,0) | I43: =B43-$O$8
...

Sheet Hacim
A1: time_corrected_s | B1: remaining_volume_mL
A2: =Sheet1!I2 | B2: =IF(ISNA(Sheet1!G2),NA(),Sheet1!$O$5-(Sheet1!G2/Sheet1!$O$6))
A3: =Sheet1!I3 | B3: =IF(ISNA(Sheet1!G3),NA(),Sheet1!$O$5-(Sheet1!G3/Sheet1!$O$6))
A4: =Sheet1!I4 | B4: =IF(ISNA(Sheet1!G4),NA(),Sheet1!$O$5-(Sheet1!G4/Sheet1!$O$6))
A5: =Sheet1!I5 | B5: =IF(ISNA(Sheet1!G5),NA(),Sheet1!$O$5-(Sheet1!G5/Sheet1!$O$6))
A6: =Sheet1!I6 | B6: =IF(ISNA(Sheet1!G6),NA(),Sheet1!$O$5-(Sheet1!G6/Sheet1!$O$6))
A7: =Sheet1!I7 | B7: =IF(ISNA(Sheet1!G7),NA(),Sheet1!$O$5-(Sheet1!G7/Sheet1!$O$6))
A8: =Sheet1!I8 | B8: =IF(ISNA(Sheet1!G8),NA(),Sheet1!$O$5-(Sheet1!G8/Sheet1!$O$6))
A9: =Sheet1!I9 | B9: =IF(ISNA(Sheet1!G9),NA(),Sheet1!$O$5-(Sheet1!G9/Sheet1!$O$6))
A10: =Sheet1!I10 | B10: =IF(ISNA(Sheet1!G10),NA(),Sheet1!$O$5-(Sheet1!G10/Sheet1!$O$6))
A11: =Sheet1!I11 | B11: =IF(ISNA(Sheet1!G11),NA(),Sheet1!$O$5-(Sheet1!G11/Sheet1!$O$6))
A12: =Sheet1!I12 | B12: =IF(ISNA(Sheet1!G12),NA(),Sheet1!$O$5-(Sheet1!G12/Sheet1!$O$6))
A13: =Sheet1!I13 | B13: =IF(ISNA(Sheet1!G13),NA(),Sheet1!$O$5-(Sheet1!G13/Sheet1!$O$6))
... A302: =Sheet1!I302 | B302: =IF(ISNA(Sheet1!G302),NA(),Sheet1!$O$5-(Sheet1!G302/Sheet1!$O$6))
